<?xml version="1.0"?>
<robot name="robo1">

    <material name="grey">
        <color rgba="0.7 0.7 0.7 1"/>
    </material>
    <material name="red">
        <color rgba="1 0 0 1"/>
    </material>
    <material name="green">
        <color rgba="0 1 0 1"/>
    </material>
    <material name="blue">
        <color rgba="0 0 1 1"/>
    </material>
    <material name="white">
        <color rgba="1 1 1 1"/>
    </material>

    <link name="base_link">
        <visual>
            <geometry>
                <box size="0.6 0.4 0.2"/>
            </geometry>
            <origin xyz="0 0 0.1" rpy="0 0 0"/>
            <material name="blue"/>
        </visual>
    </link>

    <link name="lidar">
        <visual>
            <geometry>
                <cylinder radius="0.1" length="0.05"/>
            </geometry>
            <origin xyz="0 0 0" rpy="0 0 0"/>
            <material name="white"/>
        </visual>
    </link>

    <joint name="base_to_lidar" type="fixed">
        <parent link="base_link"/>
        <child link="lidar"/>
        <origin xyz="0 0 0.225" rpy="0 0 0"/>
    </joint>

    <link name="left_wheel1">
        <visual>
            <geometry>
                <cylinder radius="0.1" length="0.05"/>
            </geometry>
            <origin xyz="0 0 0" rpy="1.57 0 0"/>
            <material name="green"/>
        </visual>
    </link>

    <joint name="base_to_left_wheel1" type="continuous">
        <parent link="base_link"/>
        <child link="left_wheel1"/>
        <origin xyz="-0.2 0.225 0" rpy="0 0 0"/>
        <axis xyz="0 1 0"/>
    </joint>

    <link name="right_wheel1">
        <visual>
            <geometry>
                <cylinder radius="0.1" length="0.05"/>
            </geometry>
            <origin xyz="0 0 0" rpy="-1.57 0 0"/>
            <material name-"green"/>
        </visual>
    </link>

    <joint name="base_to_right_wheel1" type="continuous">
        <parent link="base_link"/>
        <child link="right_wheel1"/>
        <origin xyz="0.2 0.225 0" rpy="0 0 0"/>
        <axis xyz="0 1 0"/>
    </joint>

</robot>